OpenJDK Client VM warning: You have loaded library /usr/local/hadoop-2.7.1/lib/native/libhadoop.so.1.0.0 which might have disabled stack guard. The VM will try to fix the stack guard now.
It's highly recommended that you fix the library with 'execstack -c <libfile>', or link it with '-z noexecstack'.
java.io.IOException: Failed on local exception: java.net.SocketException: Network is unreachable; Host Details : local host is: "hadoopmaster/192.168.54.130"; destination host is: "hadoopmaster":9000; 
	at org.apache.hadoop.net.NetUtils.wrapException(NetUtils.java:773)
	at org.apache.hadoop.ipc.Client.call(Client.java:1480)
	at org.apache.hadoop.ipc.Client.call(Client.java:1407)
	at org.apache.hadoop.ipc.ProtobufRpcEngine$Invoker.invoke(ProtobufRpcEngine.java:229)
	at com.sun.proxy.$Proxy9.getTransactionId(Unknown Source)
	at org.apache.hadoop.hdfs.protocolPB.NamenodeProtocolTranslatorPB.getTransactionID(NamenodeProtocolTranslatorPB.java:128)
	at sun.reflect.GeneratedMethodAccessor2.invoke(Unknown Source)
	at sun.reflect.DelegatingMethodAccessorImpl.invoke(DelegatingMethodAccessorImpl.java:43)
	at java.lang.reflect.Method.invoke(Method.java:606)
	at org.apache.hadoop.io.retry.RetryInvocationHandler.invokeMethod(RetryInvocationHandler.java:187)
	at org.apache.hadoop.io.retry.RetryInvocationHandler.invoke(RetryInvocationHandler.java:102)
	at com.sun.proxy.$Proxy10.getTransactionID(Unknown Source)
	at org.apache.hadoop.hdfs.server.namenode.SecondaryNameNode.countUncheckpointedTxns(SecondaryNameNode.java:641)
	at org.apache.hadoop.hdfs.server.namenode.SecondaryNameNode.shouldCheckpointBasedOnCount(SecondaryNameNode.java:649)
	at org.apache.hadoop.hdfs.server.namenode.SecondaryNameNode.doWork(SecondaryNameNode.java:393)
	at org.apache.hadoop.hdfs.server.namenode.SecondaryNameNode$1.run(SecondaryNameNode.java:361)
	at org.apache.hadoop.security.SecurityUtil.doAsLoginUserOrFatal(SecurityUtil.java:415)
	at org.apache.hadoop.hdfs.server.namenode.SecondaryNameNode.run(SecondaryNameNode.java:357)
	at java.lang.Thread.run(Thread.java:745)
Caused by: java.net.SocketException: Network is unreachable
	at sun.nio.ch.Net.connect0(Native Method)
	at sun.nio.ch.Net.connect(Net.java:466)
	at sun.nio.ch.Net.connect(Net.java:458)
	at sun.nio.ch.SocketChannelImpl.connect(SocketChannelImpl.java:671)
	at org.apache.hadoop.net.SocketIOWithTimeout.connect(SocketIOWithTimeout.java:192)
	at org.apache.hadoop.net.NetUtils.connect(NetUtils.java:531)
	at org.apache.hadoop.net.NetUtils.connect(NetUtils.java:495)
	at org.apache.hadoop.ipc.Client$Connection.setupConnection(Client.java:609)
	at org.apache.hadoop.ipc.Client$Connection.setupIOstreams(Client.java:707)
	at org.apache.hadoop.ipc.Client$Connection.access$2800(Client.java:370)
	at org.apache.hadoop.ipc.Client.getConnection(Client.java:1529)
	at org.apache.hadoop.ipc.Client.call(Client.java:1446)
	... 17 more
java.io.IOException: Failed on local exception: java.net.SocketException: Network is unreachable; Host Details : local host is: "hadoopmaster/192.168.54.130"; destination host is: "hadoopmaster":9000; 
	at org.apache.hadoop.net.NetUtils.wrapException(NetUtils.java:773)
	at org.apache.hadoop.ipc.Client.call(Client.java:1480)
	at org.apache.hadoop.ipc.Client.call(Client.java:1407)
	at org.apache.hadoop.ipc.ProtobufRpcEngine$Invoker.invoke(ProtobufRpcEngine.java:229)
	at com.sun.proxy.$Proxy9.getTransactionId(Unknown Source)
	at org.apache.hadoop.hdfs.protocolPB.NamenodeProtocolTranslatorPB.getTransactionID(NamenodeProtocolTranslatorPB.java:128)
	at sun.reflect.GeneratedMethodAccessor2.invoke(Unknown Source)
	at sun.reflect.DelegatingMethodAccessorImpl.invoke(DelegatingMethodAccessorImpl.java:43)
	at java.lang.reflect.Method.invoke(Method.java:606)
	at org.apache.hadoop.io.retry.RetryInvocationHandler.invokeMethod(RetryInvocationHandler.java:187)
	at org.apache.hadoop.io.retry.RetryInvocationHandler.invoke(RetryInvocationHandler.java:102)
	at com.sun.proxy.$Proxy10.getTransactionID(Unknown Source)
	at org.apache.hadoop.hdfs.server.namenode.SecondaryNameNode.countUncheckpointedTxns(SecondaryNameNode.java:641)
	at org.apache.hadoop.hdfs.server.namenode.SecondaryNameNode.shouldCheckpointBasedOnCount(SecondaryNameNode.java:649)
	at org.apache.hadoop.hdfs.server.namenode.SecondaryNameNode.doWork(SecondaryNameNode.java:393)
	at org.apache.hadoop.hdfs.server.namenode.SecondaryNameNode$1.run(SecondaryNameNode.java:361)
	at org.apache.hadoop.security.SecurityUtil.doAsLoginUserOrFatal(SecurityUtil.java:415)
	at org.apache.hadoop.hdfs.server.namenode.SecondaryNameNode.run(SecondaryNameNode.java:357)
	at java.lang.Thread.run(Thread.java:745)
Caused by: java.net.SocketException: Network is unreachable
	at sun.nio.ch.Net.connect0(Native Method)
	at sun.nio.ch.Net.connect(Net.java:466)
	at sun.nio.ch.Net.connect(Net.java:458)
	at sun.nio.ch.SocketChannelImpl.connect(SocketChannelImpl.java:671)
	at org.apache.hadoop.net.SocketIOWithTimeout.connect(SocketIOWithTimeout.java:192)
	at org.apache.hadoop.net.NetUtils.connect(NetUtils.java:531)
	at org.apache.hadoop.net.NetUtils.connect(NetUtils.java:495)
	at org.apache.hadoop.ipc.Client$Connection.setupConnection(Client.java:609)
	at org.apache.hadoop.ipc.Client$Connection.setupIOstreams(Client.java:707)
	at org.apache.hadoop.ipc.Client$Connection.access$2800(Client.java:370)
	at org.apache.hadoop.ipc.Client.getConnection(Client.java:1529)
	at org.apache.hadoop.ipc.Client.call(Client.java:1446)
	... 17 more
